<?xml version="1.0" ?>

<robot name="m2wr" xmlns:xacro="https://www.ros.org/wiki/xacro" >
        
    <link name="link_chassis">
        <!-- pose and inertial -->
        <pose>0 0 0 0 0 0</pose>
        
        <inertial>
        <mass value="5"/>
        <origin rpy="0 0 0" xyz="0 0 0.1"/>
        <inertia ixx="0.0395416666667" ixy="0" ixz="0" iyy="0.106208333333" iyz="0" izz="0.106208333333"/>
        </inertial>
        
        <collision name="collision_chassis">
        <geometry>
            <box size="0.5 0.5 0.8"/>
        </geometry>
        </collision>
        
        <visual>
        <origin rpy="0 0 0" xyz="0 0 0"/>
        <geometry>
            <box size="0.5 0.5 0.8"/>
        </geometry>
        <material name="blue"/>
        </visual>
        </link>
    
    <!-- Create wheel right -->  
        
    <link name="link_right_wheel">    
        <inertial>
        <mass value="0.2"/>
        <origin rpy="0 1.5707 1.5707" xyz="0 0 0"/>
        <inertia ixx="0.00052666666" ixy="0" ixz="0" iyy="0.00052666666" iyz="0" izz="0.001"/>
        </inertial>
        
        <collision name="link_right_wheel_collision">
        <origin rpy="0 1.5707 1.5707" xyz="0 0 0" />
        <geometry>
            <cylinder length="0.1" radius="0.2"/>
        </geometry>
        </collision>
        
        <visual name="link_right_wheel_visual">
        <origin rpy="0 1.5707 1.5707" xyz="0 0 0"/>
        <geometry>
            <cylinder length="0.1" radius="0.2"/>
        </geometry>      
        </visual>
        
    </link>
        
    <!--   Joint for right wheel  -->
    <joint name="joint_right_wheel" type="continuous">
        <origin rpy="0 0 0" xyz="0 0.3 -0.4"/>
        <child link="link_right_wheel" />
        <parent link="link_chassis"/>
        <axis rpy="0 0 0" xyz="0 -1 0"/>
        <limit effort="10000" velocity="1000"/>
        <joint_properties damping="1.0" friction="1.0" />
    </joint>  
        
    <!-- Left Wheel link -->
        
    <link name="link_left_wheel">    
        <inertial>
        <mass value="0.2"/>
        <origin rpy="0 1.5707 1.5707" xyz="0 0 0"/>
        <inertia ixx="0.00052666666" ixy="0" ixz="0" iyy="0.00052666666" iyz="0" izz="0.001"/>
        </inertial>
        
        <collision name="link_left_wheel_collision">
        <origin rpy="0 1.5707 1.5707" xyz="0 0 0" />
        <geometry>
            <cylinder length="0.1" radius="0.2"/>
        </geometry>
        </collision>
        
        <visual name="link_left_wheel_visual">
        <origin rpy="0 1.5707 1.5707" xyz="0 0 0"/>
        <geometry>
            <cylinder length="0.1" radius="0.2"/>
        </geometry>      
        </visual>
        
    </link>
        
    <!--   Joint for right wheel  -->
    <joint name="joint_left_wheel" type="continuous">
        <origin rpy="0 0 0" xyz="0 -0.3 -0.4"/>
        <child link="link_left_wheel" />
        <parent link="link_chassis"/>
        <axis rpy="0 0 0" xyz="0 1 0"/>
        <limit effort="10000" velocity="1000"/>
        <joint_properties damping="1.0" friction="1.0" />
    </joint> 
    
    
    
        
    <gazebo>
        <plugin name="differential_drive_controller" filename="libgazebo_ros_diff_drive.so">
        <update_rate>20</update_rate>
        <left_joint>joint_left_wheel</left_joint>
        <right_joint>joint_right_wheel</right_joint>
        <wheel_separation>0.4</wheel_separation>
        <wheel_diameter>0.2</wheel_diameter>
        <wheel_torque>0.1</wheel_torque>
        <command_topic>cmd_vel</command_topic>
        <odometry_topic>odom</odometry_topic>
        <odometry_frame>odom</odometry_frame>
        <robot_base_frame>link_chassis</robot_base_frame>
        </plugin>
        
        
    
    </gazebo>
    <gazebo reference="link_chassis">
        <sensor name="my_imu" type="imu">
            <always_on>true</always_on>
            <!-- Publish at 30 hz -->
            <update_rate>30</update_rate>
            <plugin name="my_imu_plugin" filename="libgazebo_ros_imu_sensor.so">
            <ros>
            <!-- Will publish to /imu/data -->
            <namespace>/imu</namespace>
            <remapping>~/out:=data</remapping>
            </ros>
            <frame_name>link_chassis</frame_name>
            <initial_orientation_as_reference>false</initial_orientation_as_reference>
            </plugin>
        </sensor>
    </gazebo>
  
  
</robot>
